<?xml version="1.0" encoding="utf-8"?>

<robot name="gimbal"
  xmlns:xacro="http://ros.org/wiki/xacro">

  <link name="base_link"/>

  <link name="yaw_link">
    <inertial>
      <origin xyz="5.0062E-05 -0.037182 0.086352" rpy="0 0 0" />
      <mass value="0.94598" />
      <inertia ixx="0.00078332" ixy="-3.16E-06" ixz="1.0358E-07" iyy="0.00060083" iyz="1.0262E-06" izz="0.0010957" />
    </inertial>
    <visual>
      <origin xyz="0 0 0" rpy="0 0 0" />
      <geometry>
        <mesh filename="package://rm_pioneer_description/meshes/yaw_link.STL" />
      </geometry>
      <material name="">
        <color rgba="0.75294 0.75294 0.75294 1" />
      </material>
    </visual>
    <collision>
      <origin xyz="0 0 0" rpy="0 0 0" />
      <geometry>
        <mesh filename="package://rm_pioneer_description/meshes/yaw_link.STL" />
      </geometry>
    </collision>
  </link>

  <joint name="yaw_joint" type="continuous">
    <origin xyz="0 0 0" rpy="0 0 0" />
    <parent link="base_link" />
    <child link="yaw_link" />
    <axis xyz="0 0 1" />
  </joint>

  <link name="pitch_link">
    <inertial>
      <origin xyz="0.034297 0.0026027 0.035447" rpy="0 0 0" />
      <mass value="1.318" />
      <inertia ixx="0.0009783" ixy="1.0555E-05" ixz="8.3659E-06" iyy="0.00092518" iyz="2.0079E-06" izz="0.0016519" />
    </inertial>
    <visual>
      <origin xyz="0 0 0" rpy="0 0 0" />
      <geometry>
        <mesh filename="package://rm_pioneer_description/meshes/pitch_link.STL" />
      </geometry>
      <material name="">
        <color rgba="0.75294 0.75294 0.75294 1" />
      </material>
    </visual>
    <collision>
      <origin xyz="0 0 0" rpy="0 0 0" />
      <geometry>
        <mesh filename="package://rm_pioneer_description/meshes/pitch_link.STL" />
      </geometry>
    </collision>
  </link>

  <joint name="pitch_joint" type="revolute">
    <!-- <origin xyz="0.0032818 0 0.097945" rpy="0 0 0" /> -->
    <origin xyz="0 0 0.163" rpy="0 0 0" />
    <parent link="yaw_link" />
    <child link="pitch_link" />
    <axis xyz="0 1 0" />
    <limit lower="-0.6" upper="0.5" effort="1.2" velocity="31"/>
  </joint>

  <link name="shooter_link" />

  <joint name="shooter_joint" type="fixed">
    <origin xyz="0 0 0.163" rpy="0 0 0" />
    <parent link="base_link" />
    <child link="shooter_link" />
  </joint>

  <link name="camera_base_link">
    <inertial>
      <origin xyz="-0.45111 0.035515 0.068286" rpy="0 0 0" />
      <mass value="0" />
      <inertia ixx="0" ixy="0" ixz="0" iyy="0" iyz="0" izz="0" />
    </inertial>
    <visual>
      <origin xyz="0 0 0" rpy="0 0 0" />
      <geometry>
        <mesh filename="package://rm_pioneer_description/meshes/camera_base_link.STL" />
      </geometry>
      <material name="">
        <color rgba="0.79216 0.81961 0.93333 1" />
      </material>
    </visual>
    <collision>
      <origin xyz="0 0 0" rpy="0 0 0" />
      <geometry>
        <mesh filename="package://rm_pioneer_description/meshes/camera_base_link.STL" />
      </geometry>
    </collision>
  </link>

  <joint name="camera_base_joint" type="fixed">
    <origin xyz="0.0806 0 0.0518" rpy="0 0 0" />
    <parent link="pitch_link" />
    <child link="camera_base_link" />
    <axis xyz="0 0 0" />
  </joint>

  <link name="camera_optical_frame" />

  <joint name="camera_optical_joint" type="fixed">
    <origin xyz="0 0 0" rpy="${-pi/2} 0 ${-pi/2}" />
    <parent link="camera_base_link" />
    <child link="camera_optical_frame" />
  </joint>

</robot>
